main()
Process Process-2:
Traceback (most recent call last):
  File "/opt/homebrew/Cellar/python@3.11/3.11.2_1/Frameworks/Python.framework/Versions/3.11/lib/python3.11/multiprocessing/managers.py", line 814, in _callmethod
    conn = self._tls.connection
           ^^^^^^^^^^^^^^^^^^^^
AttributeError: 'ForkAwareLocal' object has no attribute 'connection'

During handling of the above exception, another exception occurred:

Traceback (most recent call last):
  File "/opt/homebrew/Cellar/python@3.11/3.11.2_1/Frameworks/Python.framework/Versions/3.11/lib/python3.11/multiprocessing/process.py", line 314, in _bootstrap
    self.run()
  File "/opt/homebrew/Cellar/python@3.11/3.11.2_1/Frameworks/Python.framework/Versions/3.11/lib/python3.11/multiprocessing/process.py", line 108, in run
    self._target(*self._args, **self._kwargs)
  File "/Users/linogerlach/Projects/DUNE/WireCell/promptprocessing/scripts/run_socket_batch_new.py", line 38, in worker
    job = q.get()
          ^^^^^^^
  File "<string>", line 2, in get
  File "/opt/homebrew/Cellar/python@3.11/3.11.2_1/Frameworks/Python.framework/Versions/3.11/lib/python3.11/multiprocessing/managers.py", line 818, in _callmethod
    self._connect()
  File "/opt/homebrew/Cellar/python@3.11/3.11.2_1/Frameworks/Python.framework/Versions/3.11/lib/python3.11/multiprocessing/managers.py", line 805, in _connect
    conn = self._Client(self._token.address, authkey=self._authkey)
           ^^^^^^^^^^^^^^^^^^^^^^^^^^^^^^^^^^^^^^^^^^^^^^^^^^^^^^^^
  File "/opt/homebrew/Cellar/python@3.11/3.11.2_1/Frameworks/Python.framework/Versions/3.11/lib/python3.11/multiprocessing/connection.py", line 501, in Client
    c = SocketClient(address)
        ^^^^^^^^^^^^^^^^^^^^^
  File "/opt/homebrew/Cellar/python@3.11/3.11.2_1/Frameworks/Python.framework/Versions/3.11/lib/python3.11/multiprocessing/connection.py", line 629, in SocketClient
    s.connect(address)
FileNotFoundError: [Errno 2] No such file or directory
worker()
